<robot name="mimic_test">

  <link name="base_link"/>
  <link name="child_link"/>

  <joint name="parent_joint" type="revolute">
    <parent link="base_link"/>
    <child link="child_link"/>
    <origin xyz="0 0 0" rpy="0 0 0"/>
    <axis xyz="0 0 1"/>
    <limit lower="-3.14" upper="3.14" effort="1" velocity="1"/>
  </joint>

  <link name="mimic_link"/>

  <joint name="mimic_joint" type="revolute">
    <parent link="child_link"/>
    <child link="mimic_link"/>
    <origin xyz="1 0 0" rpy="0 0 0"/>
    <axis xyz="0 0 1"/>
    <limit lower="-3.14" upper="3.14" effort="1" velocity="1"/>
    <mimic joint="parent_joint" multiplier="1.0" offset="0.0"/>
  </joint>

</robot>

